Traceback (most recent call last):
  File "/opt/hostedtoolcache/Python/3.9.16/x64/lib/python3.9/site-packages/jupyter_cache/executors/utils.py", line 58, in single_nb_execution
    executenb(
  File "/opt/hostedtoolcache/Python/3.9.16/x64/lib/python3.9/site-packages/nbclient/client.py", line 1204, in execute
    return NotebookClient(nb=nb, resources=resources, km=km, **kwargs).execute()
  File "/opt/hostedtoolcache/Python/3.9.16/x64/lib/python3.9/site-packages/nbclient/util.py", line 84, in wrapped
    return just_run(coro(*args, **kwargs))
  File "/opt/hostedtoolcache/Python/3.9.16/x64/lib/python3.9/site-packages/nbclient/util.py", line 62, in just_run
    return loop.run_until_complete(coro)
  File "/opt/hostedtoolcache/Python/3.9.16/x64/lib/python3.9/asyncio/base_events.py", line 647, in run_until_complete
    return future.result()
  File "/opt/hostedtoolcache/Python/3.9.16/x64/lib/python3.9/site-packages/nbclient/client.py", line 663, in async_execute
    await self.async_execute_cell(
  File "/opt/hostedtoolcache/Python/3.9.16/x64/lib/python3.9/site-packages/nbclient/client.py", line 965, in async_execute_cell
    await self._check_raise_for_error(cell, cell_index, exec_reply)
  File "/opt/hostedtoolcache/Python/3.9.16/x64/lib/python3.9/site-packages/nbclient/client.py", line 862, in _check_raise_for_error
    raise CellExecutionError.from_cell_and_msg(cell, exec_reply_content)
nbclient.exceptions.CellExecutionError: An error occurred while executing the following cell:
------------------
pm.model_to_graphviz(two_level_hgf)
------------------

[0;31m---------------------------------------------------------------------------[0m
[0;31mModuleNotFoundError[0m                       Traceback (most recent call last)
File [0;32m/opt/hostedtoolcache/Python/3.9.16/x64/lib/python3.9/site-packages/pymc/model_graph.py:245[0m, in [0;36mModelGraph.make_graph[0;34m(self, var_names, formatting)[0m
[1;32m    244[0m [38;5;28;01mtry[39;00m:
[0;32m--> 245[0m     [38;5;28;01mimport[39;00m [38;5;21;01mgraphviz[39;00m
[1;32m    246[0m [38;5;28;01mexcept[39;00m [38;5;167;01mImportError[39;00m:

[0;31mModuleNotFoundError[0m: No module named 'graphviz'

During handling of the above exception, another exception occurred:

[0;31mImportError[0m                               Traceback (most recent call last)
Cell [0;32mIn[18], line 1[0m
[0;32m----> 1[0m [43mpm[49m[38;5;241;43m.[39;49m[43mmodel_to_graphviz[49m[43m([49m[43mtwo_level_hgf[49m[43m)[49m

File [0;32m/opt/hostedtoolcache/Python/3.9.16/x64/lib/python3.9/site-packages/pymc/model_graph.py:454[0m, in [0;36mmodel_to_graphviz[0;34m(model, var_names, formatting)[0m
[1;32m    448[0m     warnings[38;5;241m.[39mwarn(
[1;32m    449[0m         [38;5;124m"[39m[38;5;124mFormattings other than [39m[38;5;124m'[39m[38;5;124mplain[39m[38;5;124m'[39m[38;5;124m are currently not supported.[39m[38;5;124m"[39m,
[1;32m    450[0m         [38;5;167;01mUserWarning[39;00m,
[1;32m    451[0m         stacklevel[38;5;241m=[39m[38;5;241m2[39m,
[1;32m    452[0m     )
[1;32m    453[0m model [38;5;241m=[39m pm[38;5;241m.[39mmodelcontext(model)
[0;32m--> 454[0m [38;5;28;01mreturn[39;00m [43mModelGraph[49m[43m([49m[43mmodel[49m[43m)[49m[38;5;241;43m.[39;49m[43mmake_graph[49m[43m([49m[43mvar_names[49m[38;5;241;43m=[39;49m[43mvar_names[49m[43m,[49m[43m [49m[43mformatting[49m[38;5;241;43m=[39;49m[43mformatting[49m[43m)[49m

File [0;32m/opt/hostedtoolcache/Python/3.9.16/x64/lib/python3.9/site-packages/pymc/model_graph.py:247[0m, in [0;36mModelGraph.make_graph[0;34m(self, var_names, formatting)[0m
[1;32m    245[0m     [38;5;28;01mimport[39;00m [38;5;21;01mgraphviz[39;00m
[1;32m    246[0m [38;5;28;01mexcept[39;00m [38;5;167;01mImportError[39;00m:
[0;32m--> 247[0m     [38;5;28;01mraise[39;00m [38;5;167;01mImportError[39;00m(
[1;32m    248[0m         [38;5;124m"[39m[38;5;124mThis function requires the python library graphviz, along with binaries. [39m[38;5;124m"[39m
[1;32m    249[0m         [38;5;124m"[39m[38;5;124mThe easiest way to install all of this is by running[39m[38;5;130;01m\n[39;00m[38;5;130;01m\n[39;00m[38;5;124m"[39m
[1;32m    250[0m         [38;5;124m"[39m[38;5;130;01m\t[39;00m[38;5;124mconda install -c conda-forge python-graphviz[39m[38;5;124m"[39m
[1;32m    251[0m     )
[1;32m    252[0m graph [38;5;241m=[39m graphviz[38;5;241m.[39mDigraph([38;5;28mself[39m[38;5;241m.[39mmodel[38;5;241m.[39mname)
[1;32m    253[0m [38;5;28;01mfor[39;00m plate_label, all_var_names [38;5;129;01min[39;00m [38;5;28mself[39m[38;5;241m.[39mget_plates(var_names)[38;5;241m.[39mitems():

[0;31mImportError[0m: This function requires the python library graphviz, along with binaries. The easiest way to install all of this is by running

	conda install -c conda-forge python-graphviz
ImportError: This function requires the python library graphviz, along with binaries. The easiest way to install all of this is by running

	conda install -c conda-forge python-graphviz

